#VRML_SIM R2023a utf8

EXTERNPROTO "https://raw.githubusercontent.com/cyberbotics/webots/R2023a/projects/objects/backgrounds/protos/TexturedBackground.proto"
EXTERNPROTO "https://raw.githubusercontent.com/cyberbotics/webots/R2023a/projects/objects/backgrounds/protos/TexturedBackgroundLight.proto"
EXTERNPROTO "https://raw.githubusercontent.com/cyberbotics/webots/R2023a/projects/objects/floors/protos/RectangleArena.proto"

WorldInfo {
}
Viewpoint {
  orientation -0.2986107568703574 0.5652425483190443 0.7689814545560285 1.2039006580567064
  position -0.2795035565358104 -0.3389343187666365 0.4386236056531152
}
TexturedBackground {
}
TexturedBackgroundLight {
}
RectangleArena {
  floorSize 3 3
}
Robot {
  translation -0.10933301079939879 0.11000000000000035 2.915408188624083e-05
  rotation -2.6673418048559586e-07 0.9999999999999585 1.0836935759587531e-07 0.1003507255775865
  children [
    InertialUnit {
    }
    GPS {
    }
    HingeJoint {
      jointParameters HingeJointParameters {
        position -0.005106957572738585
        axis 0 1 0
        anchor 0 0.055 0.02
      }
      device [
        RotationalMotor {
          name "motor_izquierdo"
        }
        PositionSensor {
          name "sensor_izquierdo"
        }
      ]
      endPoint Solid {
        translation 0 0.055 0.02
        rotation 0.9999934798032949 -0.002553459123411523 0.002553467721033308 1.5708062141144035
        children [
          DEF rueda_izquierda Shape {
            appearance PBRAppearance {
              baseColor 0.643137 0 0
              metalness 0.5
            }
            geometry Cylinder {
              height 0.01
              radius 0.02
            }
          }
        ]
        boundingObject USE rueda_izquierda
        physics Physics {
          density -1
          mass 0.012566370614359175
          centerOfMass [
            0 0 0
          ]
          inertiaMatrix [
            1.3613568165555774e-06 1.3613568165555774e-06 2.513274122871835e-06
            0 0 0
          ]
        }
        linearVelocity 5.72016981928226e-18 2.484898179387321e-16 -7.058856549235927e-16
        angularVelocity -2.039843507859926e-14 1.7190470523363208e-15 -3.181962922543657e-17
      }
    }
    HingeJoint {
      jointParameters HingeJointParameters {
        position -0.005106861609634842
        axis 0 1 0
        anchor 0 -0.055 0.02
      }
      device [
        RotationalMotor {
          name "motor_derecho"
        }
        PositionSensor {
          name "sensor_derecho"
        }
      ]
      endPoint Solid {
        translation 0 -0.055 0.02
        rotation 0.9999934800483368 -0.002553411141105878 0.002553419738565726 1.570806213869359
        children [
          DEF rueda_derecha Shape {
            appearance PBRAppearance {
              baseColor 0.643137 0 0
              metalness 0.5
            }
            geometry Cylinder {
              height 0.01
              radius 0.02
            }
          }
        ]
        name "solid(1)"
        boundingObject USE rueda_derecha
        physics Physics {
          density -1
          mass 0.012566370614359175
          centerOfMass [
            0 0 0
          ]
          inertiaMatrix [
            1.3613568165555774e-06 1.3613568165555774e-06 2.513274122871835e-06
            0 0 0
          ]
        }
        linearVelocity -1.3558095868904664e-17 -1.1107302881463758e-16 7.112392249730895e-16
        angularVelocity -1.0095628456861757e-17 2.900631164011822e-15 -7.288944706506942e-17
      }
    }
    Transform {
      translation 0 0 0.025
      children [
        DEF cuerpo Shape {
          appearance PBRAppearance {
            baseColor 0.458824 0.313726 0.482353
            metalness 0
          }
          geometry Cylinder {
            height 0.04
            radius 0.05
          }
        }
      ]
    }
  ]
  boundingObject Group {
    children [
      Transform {
        translation 0 0.055 0.02
        rotation 1 0 0 1.5707996938995747
        children [
          USE rueda_izquierda
        ]
      }
      Transform {
        translation 0 -0.055 0.02
        rotation 1 0 0 1.5707996938995747
        children [
          USE rueda_derecha
        ]
      }
      Transform {
        translation 0 0 0.025
        children [
          USE cuerpo
        ]
      }
    ]
  }
  physics Physics {
    density -1
    mass 0.3392920065876977
    centerOfMass [
      0 0 0.024629629629629633
    ]
    inertiaMatrix [
      0.0005233893360880597 0.00044966662848379315 0.0004714483375487346
      0 0 7.75725230239637e-12
    ]
  }
  linearVelocity -1.0704640390508923e-17 7.044915595365906e-18 -4.188384765713272e-17
  angularVelocity 2.137474662066014e-15 -2.28381702443901e-15 4.7944569815430497e-17
}
Robot {
  translation 0.4901642042382177 -0.011715287961813273 -8.98037783892136e-05
  rotation 1.3003901936660547e-07 8.382577497917125e-09 0.9999999999999916 0.12874707845800226
  children [
    Transform {
      translation 0.045 0 0.005
      children [
        DEF ball Shape {
          appearance PBRAppearance {
          }
          geometry Sphere {
            radius 0.005
            subdivision 2
          }
        }
      ]
    }
    Transform {
      translation -0.045 0 0.005
      children [
        DEF ball Shape {
          appearance PBRAppearance {
          }
          geometry Sphere {
            radius 0.005
            subdivision 2
          }
        }
      ]
    }
    HingeJoint {
      jointParameters HingeJointParameters {
        position 3.252585439663842
        axis 0 1 0
        anchor 0 0.055 0.02
      }
      device [
        RotationalMotor {
          name "left_motor"
        }
      ]
      endPoint Solid {
        translation 0 0.055 0.02
        rotation -0.039252010872528074 0.7065605466259579 -0.7065631419725276 3.2200561070660227
        children [
          Shape {
            appearance PBRAppearance {
              baseColor 0.8 0 0
              metalness 0.5
            }
            geometry DEF left Cylinder {
              height 0.01
              radius 0.02
            }
          }
        ]
        boundingObject USE left
        physics Physics {
        }
        linearVelocity 2.802146916970355e-13 3.718961675835975e-14 1.1944749803719095e-14
        angularVelocity -2.247425874876512e-12 1.6980105300818174e-11 -1.7473708712972063e-12
      }
    }
    HingeJoint {
      jointParameters HingeJointParameters {
        position 1.7517667515048492
        axis 0 1 0
        anchor 0 -0.055 0.02
      }
      device [
        RotationalMotor {
          name "right_motor"
        }
      ]
      endPoint Solid {
        translation 0 -0.055 0.02
        rotation 0.5078076151706513 0.6091505150512604 -0.6091527525895946 2.201847270237702
        children [
          Shape {
            appearance PBRAppearance {
              baseColor 0.8 0 0
              metalness 0.5
            }
            geometry DEF left Cylinder {
              height 0.01
              radius 0.02
            }
          }
        ]
        name "solid(1)"
        boundingObject USE left
        physics Physics {
        }
        linearVelocity -5.572500356603066e-14 -6.472060574662193e-15 1.2227465775403428e-14
        angularVelocity 3.351021604761173e-13 -3.09117276454542e-12 -1.747195355140943e-12
      }
    }
    Transform {
      translation 0 0 0.025
      children [
        DEF body Shape {
          appearance PBRAppearance {
            baseColor 0.458824 0.313726 0.482353
            metalness 0.5
          }
          geometry Cylinder {
            height 0.04
            radius 0.05
          }
        }
      ]
    }
  ]
  name "robot(1)"
  boundingObject Group {
    children [
      Transform {
        translation 0.045 0 0.005
        children [
          USE ball
        ]
      }
      Transform {
        translation -0.045 0 0.005
        children [
          USE ball
        ]
      }
      Transform {
        translation 0 0 0.025
        children [
          USE body
        ]
      }
    ]
  }
  physics Physics {
    density -1
    mass 0.31415926535897937
    centerOfMass [
      0 0 0.025
    ]
    inertiaMatrix [
      0.00043458698374658825 0.00043458698374658825 0.00039269908169872427
      0 0 0
    ]
  }
  linearVelocity 5.302037742571323e-14 7.37024918146995e-15 -3.4512664603419266e-31
  angularVelocity -6.9614553882027636e-15 -1.0218646778889473e-14 -1.7472738486923612e-12
}
