#VRML_SIM R2023a utf8

EXTERNPROTO "https://raw.githubusercontent.com/cyberbotics/webots/R2023a/projects/objects/backgrounds/protos/TexturedBackground.proto"
EXTERNPROTO "https://raw.githubusercontent.com/cyberbotics/webots/R2023a/projects/objects/backgrounds/protos/TexturedBackgroundLight.proto"
EXTERNPROTO "https://raw.githubusercontent.com/cyberbotics/webots/R2023a/projects/objects/floors/protos/RectangleArena.proto"

WorldInfo {
}
Viewpoint {
  orientation 0.06399049226772723 -0.05955494368090616 -0.9961718855611706 4.636746240565936
  position 0.25335089569425556 -1.1619198312009198 0.12432844173414336
}
TexturedBackground {
}
TexturedBackgroundLight {
}
RectangleArena {
  floorSize 3 3
}
Robot {
  translation 0.061985317603533166 -0.017637994181261763 0.009389473031563796
  children [
    DEF Body_complete Group {
      children [
        Hinge2Joint {
          jointParameters HingeJointParameters {
            axis 0 0 1
            anchor 0.085 0 0.005
          }
          jointParameters2 JointParameters {
            axis 0 1 0
          }
          endPoint Solid {
            translation 0.085 0 0.005
            rotation -0.9999999999999999 0 0 1.5707953071795862
            children [
              DEF castor Shape {
                appearance PBRAppearance {
                  baseColor 0.643137 0 0
                  metalness 0.5
                }
                geometry Cylinder {
                  height 0.01
                  radius 0.01
                }
              }
            ]
            name "solid(1)"
          }
        }
        Hinge2Joint {
          jointParameters HingeJointParameters {
            axis 0 0 1
            anchor -0.085 0 0.005
          }
          jointParameters2 JointParameters {
            axis 0 1 0
          }
          endPoint Solid {
            translation -0.085 0 0.005
            rotation -0.9999999999999999 3.925233147823856e-16 0 1.5707953071795862
            children [
              DEF castor Shape {
                appearance PBRAppearance {
                  baseColor 0.643137 0 0
                  metalness 0.5
                }
                geometry Cylinder {
                  height 0.01
                  radius 0.01
                }
              }
            ]
            name "solid(2)"
          }
        }
        HingeJoint {
          jointParameters HingeJointParameters {
            position 16.6524004724336
            axis 0 1 0
            anchor 0 0 0.02
            suspensionAxis 0 0 1
          }
          device [
            PositionSensor {
              name "left_sensor"
            }
            RotationalMotor {
              name "left_motor"
              maxTorque 20
            }
          ]
          endPoint Solid {
            translation 0 0.10600000000000011 0.02
            rotation -0.2661130381600082 0.6816085525572535 -0.6816110562498646 3.6617617228140373
            children [
              DEF left Shape {
                appearance PBRAppearance {
                  baseColor 0.643137 0 0
                  metalness 0.5
                }
                geometry Cylinder {
                  height 0.01
                  radius 0.03
                }
              }
            ]
            boundingObject USE left
          }
        }
        Solid {
          translation 0 0 0.029975369178726438
          children [
            DEF body Shape {
              appearance PBRAppearance {
                baseColor 0.203922 0.396078 0.643137
                metalness 0.1
              }
              geometry Cylinder {
                height 0.05
                radius 0.1
              }
            }
          ]
          name "solid(5)"
          boundingObject USE body
        }
        HingeJoint {
          jointParameters HingeJointParameters {
            position 25.3644766632531
            axis 0 1 0
            anchor 0 0 0.02
            suspensionAxis 0 0 1
          }
          device [
            PositionSensor {
              name "right_sensor"
            }
            RotationalMotor {
              name "right_motor"
              maxTorque 50
            }
          ]
          endPoint Solid {
            translation 0 -0.10600000000000005 0.02
            rotation 0.9867228266927041 0.11484329843644184 -0.11484372028020659 1.5841657047144952
            children [
              DEF right Shape {
                appearance PBRAppearance {
                  baseColor 0.643137 0 0
                  metalness 0.5
                }
                geometry Cylinder {
                  height 0.01
                  radius 0.03
                }
              }
            ]
            name "solid(4)"
            boundingObject USE right
          }
        }
      ]
    }
  ]
  selfCollision TRUE
}
