#VRML_SIM R2023a utf8

EXTERNPROTO "https://raw.githubusercontent.com/cyberbotics/webots/R2023a/projects/objects/backgrounds/protos/TexturedBackground.proto"
EXTERNPROTO "https://raw.githubusercontent.com/cyberbotics/webots/R2023a/projects/objects/backgrounds/protos/TexturedBackgroundLight.proto"
EXTERNPROTO "https://raw.githubusercontent.com/cyberbotics/webots/R2023a/projects/objects/floors/protos/RectangleArena.proto"

WorldInfo {
}
Viewpoint {
  orientation -0.1669416319404116 0.510563464419895 0.8434781801117481 0.7396483229597302
  position -0.1307148001700622 -0.7025253675652139 0.44091453062295816
}
TexturedBackground {
}
TexturedBackgroundLight {
}
RectangleArena {
  floorSize 3 3
}
Robot {
  translation -0.06653392422674519 0.10999602477335914 2.9154082117701513e-05
  rotation 3.0001112487861426e-05 0.999999818822825 -0.0006012106539736047 0.10035074373358777
  children [
    InertialUnit {
    }
    GPS {
    }
    HingeJoint {
      jointParameters HingeJointParameters {
        position 1.446825032920919
        axis 0 1 0
        anchor 0 0.055 0.02
      }
      device [
        RotationalMotor {
          name "motor_izquierdo"
          maxTorque 50
        }
        PositionSensor {
          name "sensor_izquierdo"
        }
      ]
      endPoint Solid {
        translation 0 0.055 0.02
        rotation 0.6250232602689826 0.5519709559356388 -0.5519728144811381 2.0243635969363756
        children [
          DEF rueda_izquierda Shape {
            appearance PBRAppearance {
              baseColor 0.643137 0 0
              metalness 0.5
            }
            geometry Cylinder {
              height 0.01
              radius 0.02
            }
          }
        ]
        boundingObject USE rueda_izquierda
        physics Physics {
          density -1
          mass 0.012566370614359175
          centerOfMass [
            0 0 0
          ]
          inertiaMatrix [
            1.3613568165555774e-06 1.3613568165555774e-06 2.513274122871835e-06
            0 0 0
          ]
        }
      }
    }
    HingeJoint {
      jointParameters HingeJointParameters {
        position 0.38464697697775574
        axis 0 1 0
        anchor 0 -0.055 0.02
      }
      device [
        RotationalMotor {
          name "motor_derecho"
          maxTorque 50
        }
        PositionSensor {
          name "sensor_derecho"
        }
      ]
      endPoint Solid {
        translation 0 -0.055 0.02
        rotation 0.9641092398493358 0.18774069388199544 -0.18774132602557927 1.6073422274887257
        children [
          DEF rueda_derecha Shape {
            appearance PBRAppearance {
              baseColor 0.643137 0 0
              metalness 0.5
            }
            geometry Cylinder {
              height 0.01
              radius 0.02
            }
          }
        ]
        name "solid(1)"
        boundingObject USE rueda_derecha
        physics Physics {
          density -1
          mass 0.012566370614359175
          centerOfMass [
            0 0 0
          ]
          inertiaMatrix [
            1.3613568165555774e-06 1.3613568165555774e-06 2.513274122871835e-06
            0 0 0
          ]
        }
      }
    }
    Transform {
      translation 0 0 0.025
      children [
        DEF cuerpo Shape {
          appearance PBRAppearance {
            baseColor 0.458824 0.313726 0.482353
            metalness 0
          }
          geometry Cylinder {
            height 0.04
            radius 0.05
          }
        }
      ]
    }
  ]
  boundingObject Group {
    children [
      Transform {
        translation 0 0.055 0.02
        rotation 1 0 0 1.5707996938995747
        children [
          USE rueda_izquierda
        ]
      }
      Transform {
        translation 0 -0.055 0.02
        rotation 1 0 0 1.5707996938995747
        children [
          USE rueda_derecha
        ]
      }
      Transform {
        translation 0 0 0.025
        children [
          USE cuerpo
        ]
      }
    ]
  }
  physics Physics {
    density -1
    mass 0.3392920065876977
    centerOfMass [
      0 0 0.024629629629629633
    ]
    inertiaMatrix [
      0.0005233893360880597 0.00044966662848379315 0.0004714483375487346
      0 0 7.75725230239637e-12
    ]
  }
  controller "robot_movil"
}
Robot {
  translation 0.504570333653055 -0.01121484613308508 -8.980394034031891e-05
  rotation -7.432450560495745e-08 -1.3039263640525944e-08 -0.9999999999999971 0.1368781805206992
  children [
    InertialUnit {
    }
    GPS {
    }
    Transform {
      translation 0.045 0 0.005
      children [
        DEF ball Shape {
          appearance PBRAppearance {
          }
          geometry Sphere {
            radius 0.005
            subdivision 2
          }
        }
      ]
    }
    Transform {
      translation -0.045 0 0.005
      children [
        DEF ball Shape {
          appearance PBRAppearance {
          }
          geometry Sphere {
            radius 0.005
            subdivision 2
          }
        }
      ]
    }
    HingeJoint {
      jointParameters HingeJointParameters {
        position 5.181719681662846
        axis 0 1 0
        anchor 0 0.055 0.02
      }
      device [
        PositionSensor {
          name "sensor_izquierdo"
        }
        RotationalMotor {
          name "motor_izquierdo"
        }
      ]
      endPoint Solid {
        translation 0 0.055 0.02
        rotation -0.7550085911450357 0.46365959925277317 -0.4636613023726976 4.434986937396968
        children [
          Shape {
            appearance PBRAppearance {
              baseColor 0.8 0 0
              metalness 0.5
            }
            geometry DEF left Cylinder {
              height 0.01
              radius 0.02
            }
          }
        ]
        boundingObject USE left
        physics Physics {
        }
      }
    }
    HingeJoint {
      jointParameters HingeJointParameters {
        position 1.7517667596618982
        axis 0 1 0
        anchor 0 -0.055 0.02
      }
      device [
        PositionSensor {
          name "sensor_derecho"
        }
        RotationalMotor {
          name "motor_derecho"
        }
      ]
      endPoint Solid {
        translation 0 -0.055 0.02
        rotation 0.5078076120455092 0.6091505163539599 -0.6091527538921103 2.201847275206866
        children [
          Shape {
            appearance PBRAppearance {
              baseColor 0.8 0 0
              metalness 0.5
            }
            geometry DEF left Cylinder {
              height 0.01
              radius 0.02
            }
          }
        ]
        name "solid(1)"
        boundingObject USE left
        physics Physics {
        }
      }
    }
    Transform {
      translation 0 0 0.025
      children [
        DEF body Shape {
          appearance PBRAppearance {
            baseColor 0.458824 0.313726 0.482353
            metalness 0.5
          }
          geometry Cylinder {
            height 0.04
            radius 0.05
          }
        }
      ]
    }
  ]
  name "robot(1)"
  boundingObject Group {
    children [
      Transform {
        translation 0.045 0 0.005
        children [
          USE ball
        ]
      }
      Transform {
        translation -0.045 0 0.005
        children [
          USE ball
        ]
      }
      Transform {
        translation 0 0 0.025
        children [
          USE body
        ]
      }
    ]
  }
  physics Physics {
    density -1
    mass 0.31415926535897937
    centerOfMass [
      0 0 0.025
    ]
    inertiaMatrix [
      0.00043458698374658825 0.00043458698374658825 0.00039269908169872427
      0 0 0
    ]
  }
}
