#VRML_SIM R2023a utf8

EXTERNPROTO "https://raw.githubusercontent.com/cyberbotics/webots/R2023a/projects/objects/backgrounds/protos/TexturedBackground.proto"
EXTERNPROTO "https://raw.githubusercontent.com/cyberbotics/webots/R2023a/projects/objects/backgrounds/protos/TexturedBackgroundLight.proto"
EXTERNPROTO "https://raw.githubusercontent.com/cyberbotics/webots/R2023a/projects/objects/floors/protos/RectangleArena.proto"

WorldInfo {
}
Viewpoint {
  orientation -0.17876597442443412 0.43986908258996904 0.8800897207498459 0.8652284452988301
  position -0.04070645972146314 -0.7876818335142384 0.4497178338361568
}
TexturedBackground {
}
TexturedBackgroundLight {
}
RectangleArena {
  floorSize 3 3
}
Robot {
  translation 0.5540067062631258 -0.01801055999880447 -8.98037326033975e-05
  rotation -3.816836377725215e-05 -0.0005579242509644635 -0.9999998436318408 0.13687832147786924
  children [
    InertialUnit {
    }
    GPS {
    }
    Transform {
      translation 0.045 0 0.005
      children [
        DEF ball Shape {
          appearance PBRAppearance {
          }
          geometry Sphere {
            radius 0.005
            subdivision 2
          }
        }
      ]
    }
    Transform {
      translation -0.045 0 0.005
      children [
        DEF ball Shape {
          appearance PBRAppearance {
          }
          geometry Sphere {
            radius 0.005
            subdivision 2
          }
        }
      ]
    }
    HingeJoint {
      jointParameters HingeJointParameters {
        position 7.677719019438842
        axis 0 1 0
        anchor 0 0.055 0.02
      }
      device [
        PositionSensor {
          name "sensor_izquierdo"
        }
        RotationalMotor {
          name "motor_izquierdo"
        }
      ]
      endPoint Solid {
        translation 0 0.055 0.02
        rotation -0.6450629493469806 -0.5403201118865272 0.540322096596748 4.287382709898208
        children [
          Shape {
            appearance PBRAppearance {
              baseColor 0.8 0 0
              metalness 0.5
            }
            geometry DEF left Cylinder {
              height 0.01
              radius 0.02
            }
          }
        ]
        boundingObject USE left
        physics Physics {
        }
        linearVelocity 0.009900258395986154 -0.0013612380361749605 3.21959054789614e-09
        angularVelocity 0.06820387846462589 0.4951652985970635 -5.3764594914123676e-08
      }
    }
    HingeJoint {
      jointParameters HingeJointParameters {
        position 4.247766096992192
        axis 0 1 0
        anchor 0 -0.055 0.02
      }
      device [
        PositionSensor {
          name "sensor_derecho"
        }
        RotationalMotor {
          name "motor_derecho"
        }
      ]
      endPoint Solid {
        translation 0 -0.055 0.02
        rotation -0.40008057900796357 0.6480480094270639 -0.6480503898450125 3.9027417996686613
        children [
          Shape {
            appearance PBRAppearance {
              baseColor 0.8 0 0
              metalness 0.5
            }
            geometry DEF left Cylinder {
              height 0.01
              radius 0.02
            }
          }
        ]
        name "solid(1)"
        boundingObject USE left
        physics Physics {
        }
        linearVelocity 0.009900254871724338 -0.0013612375507291883 1.7390494115759538e-09
        angularVelocity 0.06820387845019737 0.49516529845565815 -5.3751358854862355e-08
      }
    }
    Transform {
      translation 0 0 0.025
      children [
        DEF body Shape {
          appearance PBRAppearance {
            baseColor 0.458824 0.313726 0.482353
            metalness 0.5
          }
          geometry Cylinder {
            height 0.04
            radius 0.05
          }
        }
      ]
    }
  ]
  name "robot(1)"
  boundingObject Group {
    children [
      Transform {
        translation 0.045 0 0.005
        children [
          USE ball
        ]
      }
      Transform {
        translation -0.045 0 0.005
        children [
          USE ball
        ]
      }
      Transform {
        translation 0 0 0.025
        children [
          USE body
        ]
      }
    ]
  }
  physics Physics {
    density -1
    mass 0.31415926535897937
    centerOfMass [
      0 0 0.025
    ]
    inertiaMatrix [
      0.00043458698374658825 0.00043458698374658825 0.00039269908169872427
      0 0 0
    ]
  }
  controller "robot_movil"
  linearVelocity 0.009899337526811974 -0.001361109725107244 -1.293129736469058e-10
  angularVelocity -2.1743179171931176e-05 -0.0001579577619422657 -5.121815548662188e-08
}
